<?xml version="1.0" encoding="utf-8"?>
<!-- This URDF was automatically created by SolidWorks to URDF Exporter! Originally created by Stephen Brawner (brawner@gmail.com) 
     Commit Version: 1.6.0-4-g7f85cfe  Build Version: 1.6.7995.38578
     For more information, please see http://wiki.ros.org/sw_urdf_exporter -->
<robot
  name="six_dof_arm">
  <link
    name="base_link">
    <inertial>
      <origin
        xyz="0.150569577094829 -0.282065557059584 0.0858444903709998"
        rpy="0 0 0" />
      <mass
        value="3.82869416281393" />
      <inertia
        ixx="0.0231805999397633"
        ixy="-9.35626509492742E-07"
        ixz="0.000718143477106582"
        iyy="0.023829421434195"
        iyz="6.20025735268592E-07"
        izz="0.0401642921599346" />
    </inertial>
    <visual>
      <origin
        xyz="0 0 0"
        rpy="0 0 0" />
      <geometry>
        <mesh
          filename="package://six_dof_arm/meshes/base_link.STL" />
      </geometry>
      <material
        name="">
        <color
          rgba="0.247058823529412 0.23921568627451 0.235294117647059 1" />
      </material>
    </visual>
    <collision>
      <origin
        xyz="0 0 0"
        rpy="0 0 0" />
      <geometry>
        <mesh
          filename="package://six_dof_arm/meshes/base_link.STL" />
      </geometry>
    </collision>
  </link>
  <link
    name="link_1">
    <inertial>
      <origin
        xyz="4.32383283317378E-05 0.0680624071651353 6.52562397435164E-06"
        rpy="0 0 0" />
      <mass
        value="0.496365683666781" />
      <inertia
        ixx="0.000792847522971884"
        ixy="-3.73013993388821E-07"
        ixz="1.80968680807939E-05"
        iyy="0.000184926812457533"
        iyz="-4.97697758356282E-09"
        izz="0.000717881898216823" />
    </inertial>
    <visual>
      <origin
        xyz="0 0 0"
        rpy="0 0 0" />
      <geometry>
        <mesh
          filename="package://six_dof_arm/meshes/link_1.STL" />
      </geometry>
      <material
        name="">
        <color
          rgba="0.898039215686275 0.917647058823529 0.929411764705882 1" />
      </material>
    </visual>
    <collision>
      <origin
        xyz="0 0 0"
        rpy="0 0 0" />
      <geometry>
        <mesh
          filename="package://six_dof_arm/meshes/link_1.STL" />
      </geometry>
    </collision>
  </link>
  <joint
    name="joint_1"
    type="continuous">
    <origin
      xyz="0.15423 -0.28206 0.10149"
      rpy="1.5708 0 0.43749" />
    <parent
      link="base_link" />
    <child
      link="link_1" />
    <axis
      xyz="0 1 0" />
  </joint>
  <link
    name="link_2">
    <inertial>
      <origin
        xyz="0.0338354479920845 -0.0064322169652048 -0.00245407284264082"
        rpy="0 0 0" />
      <mass
        value="0.252006469213197" />
      <inertia
        ixx="6.24106980967512E-05"
        ixy="2.122889857404E-05"
        ixz="8.94621229356148E-06"
        iyy="0.000169543347753182"
        iyz="-3.84314642165744E-07"
        izz="0.000182079065869168" />
    </inertial>
    <visual>
      <origin
        xyz="0 0 0"
        rpy="0 0 0" />
      <geometry>
        <mesh
          filename="package://six_dof_arm/meshes/link_2.STL" />
      </geometry>
      <material
        name="">
        <color
          rgba="0.898039215686275 0.917647058823529 0.929411764705882 1" />
      </material>
    </visual>
    <collision>
      <origin
        xyz="0 0 0"
        rpy="0 0 0" />
      <geometry>
        <mesh
          filename="package://six_dof_arm/meshes/link_2.STL" />
      </geometry>
    </collision>
  </link>
  <joint
    name="joint_2"
    type="revolute">
    <origin
      xyz="0 0.112 0"
      rpy="1.5708 0 2.4755" />
    <parent
      link="link_1" />
    <child
      link="link_2" />
    <axis
      xyz="0 1 0" />
    <limit
      lower="-1.57"
      upper="1.57"
      effort="10"
      velocity="1.57" />
  </joint>
  <link
    name="link_3">
    <inertial>
      <origin
        xyz="-0.0270205188287359 -0.00383049369840976 -0.0142531927255568"
        rpy="0 0 0" />
      <mass
        value="0.343635149193939" />
      <inertia
        ixx="0.00028538664881932"
        ixy="-9.66773270784163E-06"
        ixz="-4.92482264612374E-06"
        iyy="0.000529175475076648"
        iyz="4.3261957062028E-05"
        izz="0.000338633695459992" />
    </inertial>
    <visual>
      <origin
        xyz="0 0 0"
        rpy="0 0 0" />
      <geometry>
        <mesh
          filename="package://six_dof_arm/meshes/link_3.STL" />
      </geometry>
      <material
        name="">
        <color
          rgba="0.898039215686275 0.917647058823529 0.929411764705882 1" />
      </material>
    </visual>
    <collision>
      <origin
        xyz="0 0 0"
        rpy="0 0 0" />
      <geometry>
        <mesh
          filename="package://six_dof_arm/meshes/link_3.STL" />
      </geometry>
    </collision>
  </link>
  <joint
    name="joint_3"
    type="revolute">
    <origin
      xyz="0.065 0 0"
      rpy="1.5708 0.62232 3.1416" />
    <parent
      link="link_2" />
    <child
      link="link_3" />
    <axis
      xyz="0 0 1" />
    <limit
      lower="-1.57"
      upper="1.57"
      effort="10"
      velocity="1.57" />
  </joint>
  <link
    name="link_4">
    <inertial>
      <origin
        xyz="0.00315043687013407 0.00823334083490718 -0.0153088125607234"
        rpy="0 0 0" />
      <mass
        value="0.458108386971292" />
      <inertia
        ixx="0.000266524923789775"
        ixy="-4.83010597650581E-05"
        ixz="-2.58452901540373E-05"
        iyy="0.000231242852741601"
        iyz="-7.692645775569E-06"
        izz="0.000378867067607329" />
    </inertial>
    <visual>
      <origin
        xyz="0 0 0"
        rpy="0 0 0" />
      <geometry>
        <mesh
          filename="package://six_dof_arm/meshes/link_4.STL" />
      </geometry>
      <material
        name="">
        <color
          rgba="0.898039215686275 0.917647058823529 0.929411764705882 1" />
      </material>
    </visual>
    <collision>
      <origin
        xyz="0 0 0"
        rpy="0 0 0" />
      <geometry>
        <mesh
          filename="package://six_dof_arm/meshes/link_4.STL" />
      </geometry>
    </collision>
  </link>
  <joint
    name="joint_4"
    type="revolute">
    <origin
      xyz="-0.0652500000000006 0 0"
      rpy="0 0 1.38288301124323" />
    <parent
      link="link_3" />
    <child
      link="link_4" />
    <axis
      xyz="0 0 1" />
    <limit
      lower="-1.57"
      upper="1.57"
      effort="10"
      velocity="1.57" />
  </joint>
  <link
    name="link_5">
    <inertial>
      <origin
        xyz="0.00289484913778473 0.00414654326045577 0.0215505654647544"
        rpy="0 0 0" />
      <mass
        value="0.126917113445138" />
      <inertia
        ixx="5.56063236989531E-05"
        ixy="-1.6838052978347E-06"
        ixz="-1.46179701383522E-06"
        iyy="3.36435019532127E-05"
        iyz="-2.18123980266177E-06"
        izz="4.54057563337419E-05" />
    </inertial>
    <visual>
      <origin
        xyz="0 0 0"
        rpy="0 0 0" />
      <geometry>
        <mesh
          filename="package://six_dof_arm/meshes/link_5.STL" />
      </geometry>
      <material
        name="">
        <color
          rgba="0.898039215686275 0.917647058823529 0.929411764705882 1" />
      </material>
    </visual>
    <collision>
      <origin
        xyz="0 0 0"
        rpy="0 0 0" />
      <geometry>
        <mesh
          filename="package://six_dof_arm/meshes/link_5.STL" />
      </geometry>
    </collision>
  </link>
  <joint
    name="joint_5"
    type="continuous">
    <origin
      xyz="0.041309 0.030815 0"
      rpy="-1.5708 -0.5334 -1.5708" />
    <parent
      link="link_4" />
    <child
      link="link_5" />
    <axis
      xyz="0 0 1" />
  </joint>
  <link
    name="link_6">
    <inertial>
      <origin
        xyz="0.0131878992229404 -0.00226095943259702 -0.012293076726409"
        rpy="0 0 0" />
      <mass
        value="0.148374429790066" />
      <inertia
        ixx="2.93261916769444E-05"
        ixy="7.3351025715348E-06"
        ixz="1.40390696102425E-05"
        iyy="6.10021376701108E-05"
        iyz="-3.137672487269E-06"
        izz="5.61863010649392E-05" />
    </inertial>
    <visual>
      <origin
        xyz="0 0 0"
        rpy="0 0 0" />
      <geometry>
        <mesh
          filename="package://six_dof_arm/meshes/link_6.STL" />
      </geometry>
      <material
        name="">
        <color
          rgba="0.898039215686275 0.917647058823529 0.929411764705882 1" />
      </material>
    </visual>
    <collision>
      <origin
        xyz="0 0 0"
        rpy="0 0 0" />
      <geometry>
        <mesh
          filename="package://six_dof_arm/meshes/link_6.STL" />
      </geometry>
    </collision>
  </link>
  <joint
    name="joint_6"
    type="revolute">
    <origin
      xyz="0 0 0.038456"
      rpy="1.5708 -1.5672 -1.5708" />
    <parent
      link="link_5" />
    <child
      link="link_6" />
    <axis
      xyz="0 0 1" />
    <limit
      lower="-1.57"
      upper="1.57"
      effort="10"
      velocity="1.57" />
  </joint>
      <ros2_control name="GazeboSimSystem" type="system">
  	<hardware>
  		<plugin>gazebo_ros2_control/GazeboSystem</plugin>
  	</hardware>
  	<joint name="joint_1">
  		<command_interface name="position"/>
  		<state_interface name="position">
  			<param name="initial_value">0.0</param>
  		</state_interface>
  		<state_interface name="velocity"/>
  	</joint>
  	<joint name="joint_2">
  		<command_interface name="position"/>
  		<state_interface name="position">
  			<param name="initial_value">0.0</param>
  		</state_interface>
  		<state_interface name="velocity"/>
  	</joint>
  	<joint name="joint_3">
  		<command_interface name="position"/>
  		<state_interface name="position">
  			<param name="initial_value">0.0</param>
  		</state_interface>
  		<state_interface name="velocity"/>
  	</joint>
  	<joint name="joint_4">
  		<command_interface name="position"/>
  		<state_interface name="position">
  			<param name="initial_value">0.0</param>
  		</state_interface>
  		<state_interface name="velocity"/>
  	</joint>
  	<joint name="joint_5">
  		<command_interface name="position"/>
  		<state_interface name="position">
  			<param name="initial_value">0.0</param>
  		</state_interface>
  		<state_interface name="velocity"/>
  	</joint>
  	<joint name="joint_6">
  		<command_interface name="position"/>
  		<state_interface name="position">
  			<param name="initial_value">0.0</param>
  		</state_interface>
  		<state_interface name="velocity"/>
  	</joint>
  </ros2_control>
  <gazebo>
  	<plugin name="gazebo_ros2_control" filename="libgazebo_ros2_control.so">
  		<parameters>$(find six_dof_arm)/config/joint_names_six_dof_arm.yaml</parameters>
  	</plugin>
  </gazebo>
</robot>
